Workbook
Name Slicer_Category: #N/A
Name Slicer_Customer_Type: #N/A
Name Slicer_Region: #N/A

Sheet Raw_Data
A1: Order ID | B1: Order Date | C1: Region | D1: Category | E1: Product | F1: Customer Type | G1: Quantity | H1: Sales | I1: Profit | J1: Payment Mode
A2: ORD-0001 | B2: 2025-03-13 | C2: North | D2: Home | E2: Blender | F2: New | G2: 1 | H2: 3354.59 | I2: 27.38 | J2: Net Banking
A3: ORD-0002 | B3: 2025-01-14 | C3: South | D3: Electronics | E3: Laptop | F3: Existing | G3: 1 | H3: 49073.83 | I3: 5001.99 | J3: Card
A4: ORD-0003 | B4: 2025-03-23 | C4: West | D4: Clothing | E4: Dress | F4: Existing | G4: 3 | H4: 6052.75 | I4: -470.06 | J4: Cash
A5: ORD-0004 | B5: 2025-07-03 | C5: East | D5: Electronics | E5: Headphones | F5: Existing | G5: 3 | H5: 6903.32 | I5: 391.93 | J5: UPI
A6: ORD-0005 | B6: 2025-02-10 | C6: East | D6: Home | E6: Cookware Set | F6: Existing | G6: 5 | H6: 12949.51 | I6: 3263.62 | J6: Card
A7: ORD-0006 | B7: 2025-02-10 | C7: South | D7: Home | E7: Blender | F7: New | G7: 1 | H7: 3303.21 | I7: 655.04 | J7: Net Banking
A8: ORD-0007 | B8: 2025-12-10 | C8: East | D8: Clothing | E8: Sneakers | F8: New | G8: 3 | H8: 9791.57 | I8: 468.99 | J8: Card
A9: ORD-0008 | B9: 2025-11-24 | C9: South | D9: Home | E9: Desk Lamp | F9: Existing | G9: 2 | H9: 1786.41 | I9: 30.69 | J9: UPI
A10: ORD-0009 | B10: 2025-10-18 | C10: East | D10: Electronics | E10: Laptop | F10: New | G10: 3 | H10: 152916.34 | I10: -8589.63 | J10: Net Banking
A11: ORD-0010 | B11: 2025-10-15 | C11: East | D11: Clothing | E11: Sneakers | F11: Existing | G11: 2 | H11: 6670.83 | I11: 58.61 | J11: Net Banking
A12: ORD-0011 | B12: 2025-01-25 | C12: North | D12: Clothing | E12: T-Shirt | F12: New | G12: 2 | H12: 1402.67 | I12: -66.31 | J12: Card
A13: ORD-0012 | B13: 2025-08-28 | C13: East | D13: Home | E13: Cookware Set | F13: New | G13: 5 | H13: 12777.88 | I13: 733.23 | J13: UPI
... A64: ORD-0063 | B64: 2025-04-19 | C64: West | D64: Electronics | E64: Keyboard | F64: Existing | G64: 2 | H64: 3276.2 | I64: 185.03 | J64: Cash
A65: ORD-0064 | B65: 2025-01-10 | C65: North | D65: Clothing | E65: Jeans | F65: Existing | G65: 4 | H65: 6082.91 | I65: -307.27
A66: ORD-0065 | B66: 2025-04-13 | C66: North | D66: Home | E66: Blender | F66: New | G66: 1 | H66: 3362.71 | I66: 880.56 | J66: Card
A67: ORD-0066 | B67: 2025-12-25 | C67: East | D67: Electronics | E67: Keyboard | F67: Existing | G67: 1 | H67: 1823.03 | I67: -2.79 | J67: Card
A68: ORD-0067 | B68: 2025-06-09 | C68: North | D68: Home | E68: Chair | F68: New | G68: 1 | H68: 4750.01 | I68: -99.96 | J68: Cash
A69: ORD-0068 | B69: 2025-10-31 | C69: South | D69: Home | E69: Cookware Set | F69: New | G69: 4 | H69: 12188.89 | I69: -104.84 | J69: Cash
A70: ORD-0069 | B70: 2025-01-22 | C70: East | D70: Home | E70: Chair | F70: Existing | G70: 1 | H70: 4766.6 | I70: 589.8 | J70: Cash
A71: ORD-0070 | B71: 2025-09-08 | C71: North | D71: Electronics | E71: Monitor | F71: Existing | G71: 3 | H71: 32491.1 | I71: 2314.05 | J71: Cash
A72: ORD-0071 | B72: 2025-11-30 | C72: East | D72: Home | E72: Cookware Set | F72: Existing | G72: 2 | H72: 5527.75 | I72: 1018.03 | J72: Net Banking
A73: ORD-0072 | B73: 2025-02-14 | C73: East | D73: Clothing | E73: Dress | F73: Existing | G73: 3 | H73: 5497.43 | I73: 46.06 | J73: Card
A74: ORD-0073 | B74: 2025-09-11 | C74: East | D74: Clothing | E74: Dress | F74: New | G74: 5 | H74: 9819.56 | I74: 403.61 | J74: Net Banking
A75: ORD-0074 | B75: 2025-12-26 | C75: East | D75: Electronics | E75: Smartphone | F75: New | G75: 3 | H75: 81317.69 | I75: 19265.4 | J75: Card
A76: ORD-0075 | B76: 2025-12-20 | C76: West | D76: Electronics | E76: Headphones | F76: Existing | G76: 4 | H76: 9977.16 | I76: 1924.99 | J76: Net Banking
A77: ORD-0076 | B77: 2025-06-06 | C77: East | D77: Electronics | E77: Laptop | F77: Existing | G77: 3 | H77: 147313.81 | I77: 24902.42 | J77: Cash
... A91: ORD-0090 | B91: 2025-06-05 | C91: West | D91: Home | E91: Chair | F91: Existing | G91: 3 | H91: 13335.71 | I91: 1183.29 | J91: Net Banking
A92: ORD-0091 | B92: 2025-06-15 | C92: East | D92: Clothing | E92: Jacket | G92: 5 | H92: 9987.69 | I92: 754.37 | J92: UPI
A93: ORD-0092 | B93: 2025-12-11 | C93: East | D93: Electronics | E93: Monitor | F93: New | G93: 5 | H93: 65409.44 | I93: 18304.57 | J93: Card
A94: ORD-0093 | B94: 2025-10-27 | C94: West | D94: Clothing | E94: Dress | F94: Existing | G94: 4 | H94: 8232.43 | I94: -120.72 | J94: UPI
A95: ORD-0094 | B95: 2025-03-24 | C95: East | D95: Clothing | E95: Jeans | F95: Existing | G95: 4 | H95: 6186.63 | I95: 997.58 | J95: Net Banking
A96: ORD-0095 | B96: 2025-05-10 | C96: East | D96: Clothing | E96: Sneakers | F96: New | G96: 5 | H96: 15878.44 | I96: -766.9 | J96: Net Banking
A97: ORD-0096 | B97: 2025-09-23 | C97: East | D97: Home | E97: Blender | F97: Existing | G97: 5 | H97: 15878.32 | I97: -960.42 | J97: Net Banking
A98: ORD-0097 | B98: 2025-08-13 | C98: West | D98: Electronics | E98: Headphones | F98: New | G98: 3 | H98: 7573.83 | I98: 1923.47 | J98: UPI
A99: ORD-0098 | B99: 2025-01-08 | C99: West | D99: Home | E99: Chair | F99: New | G99: 2 | H99: 9377.61 | I99: 298.86 | J99: Card
A100: ORD-0099 | B100: 2025-05-30 | C100: East | D100: Electronics | E100: Keyboard | F100: Existing | G100: 1 | H100: 1853.18 | I100: -45.53 | J100: Net Banking
A101: ORD-0100 | B101: 2025-11-03 | C101: South | D101: Clothing | E101: T-Shirt | F101: New | G101: 4 | H101: 2828.71 | I101: 164.32 | J101: Cash
A102: ORD-0101 | B102: 2025-06-02 | C102: West | D102: Clothing | E102: Jeans | F102: New | G102: 5 | H102: 7627.48 | I102: -603.15 | J102: Net Banking
A103: ORD-0102 | B103: 2025-07-13 | C103: West | D103: Home | E103: Cookware Set | F103: Existing | G103: 3 | H103: 8118.5 | I103: 1580.14 | J103: Card
...

Sheet Cleaned_Data
A1: Order ID | B1: Order Date | C1: Region | D1: Category | E1: Product | F1: Customer Type | G1: Quantity | H1: Sales | I1: Profit | J1: Payment Mode | K1: Clean Region. | L1: Clean Category | M1: Clean Product | N1: Data Quality Status | O1: Clean Customer Type | P1: Clean Payment Mode | Q1: Sales for Analysis | R1: Profit for Analysis
A2: ORD-0052 | B2: 2025-04-10 | C2: West | D2: Home | E2: Blender | F2: Existing | G2: 4 | H2: 12580.97 | I2: 1845.82 | J2: Net Banking | K2: =PROPER(TRIM(C2)) -> West | L2: =PROPER(TRIM(D2)) -> Home | M2: =PROPER(TRIM(E2)) -> Blender | N2: =IF(OR(H2="",I2="",J2="",F2=""),"Review","OK") -> OK | O2: =IF(TRIM(F2)="","Review",PROPER(TRIM(F2))) -> Existing | P2: =IF(TRIM(J2)="","Review",PROPER(TRIM(J2))) -> Net Banking | Q2: =IF(H2="","",H2) -> 12580.97 | R2: =IF(I2="","",I2) -> 1845.82 | S2: =COUNTBLANK(Q2:Q301) -> 1
A3: ORD-0171 | B3: 2025-08-12 | C3: North | D3: Electronics | E3: Smartphone | F3: New | G3: 4 | H3: 121078.86 | I3: -3263.62 | J3: Net Banking | K3: =PROPER(TRIM(C3)) -> North | L3: =PROPER(TRIM(D3)) -> Electronics | M3: =PROPER(TRIM(E3)) -> Smartphone | N3: =IF(OR(H3="",I3="",J3="",F3=""),"Review","OK") -> OK | O3: =IF(TRIM(F3)="","Review",PROPER(TRIM(F3))) -> New | P3: =IF(TRIM(J3)="","Review",PROPER(TRIM(J3))) -> Net Banking | Q3: =IF(H3="","",H3) -> 121078.86 | R3: =IF(I3="","",I3) -> -3263.62 | S3: =COUNTBLANK(R2:R301) -> 1
A4: ORD-0031 | B4: 2025-11-27 | C4: East | D4: Home | E4: Bedsheet | F4: Existing | G4: 2 | H4: 2668.74 | I4: -87.76 | J4: Cash | K4: =PROPER(TRIM(C4)) -> East | L4: =PROPER(TRIM(D4)) -> Home | M4: =PROPER(TRIM(E4)) -> Bedsheet | N4: =IF(OR(H4="",I4="",J4="",F4=""),"Review","OK") -> OK | O4: =IF(TRIM(F4)="","Review",PROPER(TRIM(F4))) -> Existing | P4: =IF(TRIM(J4)="","Review",PROPER(TRIM(J4))) -> Cash | Q4: =IF(H4="","",H4) -> 2668.74 | R4: =IF(I4="","",I4) -> -87.76 | S4: =COUNTIF(K2:K301,"North")+COUNTIF(K2:K301,"South")+COUNTIF(K2:K301,"East")+COUNTIF(K2:K301,"West") -> 300
A5: ORD-0112 | B5: 2025-08-27 | C5: East | D5: Home | E5: Bedsheet | F5: New | G5: 4 | H5: 5325.97 | I5: -408.06 | J5: UPI | K5: =PROPER(TRIM(C5)) -> East | L5: =PROPER(TRIM(D5)) -> Home | M5: =PROPER(TRIM(E5)) -> Bedsheet | N5: =IF(OR(H5="",I5="",J5="",F5=""),"Review","OK") -> OK | O5: =IF(TRIM(F5)="","Review",PROPER(TRIM(F5))) -> New | P5: =IF(TRIM(J5)="","Review",PROPER(TRIM(J5))) -> Upi | Q5: =IF(H5="","",H5) -> 5325.97 | R5: =IF(I5="","",I5) -> -408.06 | S5: =COUNTIF(L2:L301,"Electronics")+COUNTIF(L2:L301,"Clothing")+COUNTIF(L2:L301,"Home") -> 300
A6: ORD-0201 | B6: 2025-10-10 | C6: East | D6: Home | E6: Bedsheet | F6: New | G6: 1 | H6: 1330.17 | J6: Cash | K6: =PROPER(TRIM(C6)) -> East | L6: =PROPER(TRIM(D6)) -> Home | M6: =PROPER(TRIM(E6)) -> Bedsheet | N6: =IF(OR(H6="",I6="",J6="",F6=""),"Review","OK") -> Review | O6: =IF(TRIM(F6)="","Review",PROPER(TRIM(F6))) -> New | P6: =IF(TRIM(J6)="","Review",PROPER(TRIM(J6))) -> Cash | Q6: =IF(H6="","",H6) -> 1330.17 | R6: =IF(I6="","",I6) | S6: =COUNTIF(N2:N301,"Review") -> 4
A7: ORD-0037 | B7: 2025-08-07 | C7: North | D7: Home | E7: Bedsheet | F7: New | G7: 2 | H7: 2935.09 | I7: 348.12 | J7: UPI | K7: =PROPER(TRIM(C7)) -> North | L7: =PROPER(TRIM(D7)) -> Home | M7: =PROPER(TRIM(E7)) -> Bedsheet | N7: =IF(OR(H7="",I7="",J7="",F7=""),"Review","OK") -> OK | O7: =IF(TRIM(F7)="","Review",PROPER(TRIM(F7))) -> New | P7: =IF(TRIM(J7)="","Review",PROPER(TRIM(J7))) -> Upi | Q7: =IF(H7="","",H7) -> 2935.09 | R7: =IF(I7="","",I7) -> 348.12
A8: ORD-0120 | B8: 2025-10-02 | C8: North | D8: Home | E8: Bedsheet | F8: Existing | G8: 1 | H8: 1481.39 | I8: -111.09 | J8: Cash | K8: =PROPER(TRIM(C8)) -> North | L8: =PROPER(TRIM(D8)) -> Home | M8: =PROPER(TRIM(E8)) -> Bedsheet | N8: =IF(OR(H8="",I8="",J8="",F8=""),"Review","OK") -> OK | O8: =IF(TRIM(F8)="","Review",PROPER(TRIM(F8))) -> Existing | P8: =IF(TRIM(J8)="","Review",PROPER(TRIM(J8))) -> Cash | Q8: =IF(H8="","",H8) -> 1481.39 | R8: =IF(I8="","",I8) -> -111.09
A9: ORD-0121 | B9: 2025-07-10 | C9: North | D9: Home | E9: Bedsheet | F9: New | G9: 5 | H9: 6833.44 | I9: 1024.18 | J9: Net Banking | K9: =PROPER(TRIM(C9)) -> North | L9: =PROPER(TRIM(D9)) -> Home | M9: =PROPER(TRIM(E9)) -> Bedsheet | N9: =IF(OR(H9="",I9="",J9="",F9=""),"Review","OK") -> OK | O9: =IF(TRIM(F9)="","Review",PROPER(TRIM(F9))) -> New | P9: =IF(TRIM(J9)="","Review",PROPER(TRIM(J9))) -> Net Banking | Q9: =IF(H9="","",H9) -> 6833.44 | R9: =IF(I9="","",I9) -> 1024.18
A10: ORD-0137 | B10: 2025-08-31 | C10: North | D10: Home | E10: Bedsheet | F10: New | G10: 3 | I10: 766.2 | J10: UPI | K10: =PROPER(TRIM(C10)) -> North | L10: =PROPER(TRIM(D10)) -> Home | M10: =PROPER(TRIM(E10)) -> Bedsheet | N10: =IF(OR(H10="",I10="",J10="",F10=""),"Review","OK") -> Review | O10: =IF(TRIM(F10)="","Review",PROPER(TRIM(F10))) -> New | P10: =IF(TRIM(J10)="","Review",PROPER(TRIM(J10))) -> Upi | Q10: =IF(H10="","",H10) | R10: =IF(I10="","",I10) -> 766.2
A11: ORD-0152 | B11: 2025-09-19 | C11: North | D11: Home | E11: Bedsheet | F11: New | G11: 2 | H11: 2706.52 | I11: -52.7 | J11: Cash | K11: =PROPER(TRIM(C11)) -> North | L11: =PROPER(TRIM(D11)) -> Home | M11: =PROPER(TRIM(E11)) -> Bedsheet | N11: =IF(OR(H11="",I11="",J11="",F11=""),"Review","OK") -> OK | O11: =IF(TRIM(F11)="","Review",PROPER(TRIM(F11))) -> New | P11: =IF(TRIM(J11)="","Review",PROPER(TRIM(J11))) -> Cash | Q11: =IF(H11="","",H11) -> 2706.52 | R11: =IF(I11="","",I11) -> -52.7
A12: ORD-0116 | B12: 2025-12-14 | C12: South | D12: Home | E12: Bedsheet | F12: New | G12: 2 | H12: 2876.51 | I12: 412.84 | J12: UPI | K12: =PROPER(TRIM(C12)) -> South | L12: =PROPER(TRIM(D12)) -> Home | M12: =PROPER(TRIM(E12)) -> Bedsheet | N12: =IF(OR(H12="",I12="",J12="",F12=""),"Review","OK") -> OK | O12: =IF(TRIM(F12)="","Review",PROPER(TRIM(F12))) -> New | P12: =IF(TRIM(J12)="","Review",PROPER(TRIM(J12))) -> Upi | Q12: =IF(H12="","",H12) -> 2876.51 | R12: =IF(I12="","",I12) -> 412.84
A13: ORD-0181 | B13: 2025-11-26 | C13: South | D13: Home | E13: Bedsheet | F13: Existing | G13: 2 | H13: 2544.83 | I13: 296.64 | J13: Net Banking | K13: =PROPER(TRIM(C13)) -> South | L13: =PROPER(TRIM(D13)) -> Home | M13: =PROPER(TRIM(E13)) -> Bedsheet | N13: =IF(OR(H13="",I13="",J13="",F13=""),"Review","OK") -> OK | O13: =IF(TRIM(F13)="","Review",PROPER(TRIM(F13))) -> Existing | P13: =IF(TRIM(J13)="","Review",PROPER(TRIM(J13))) -> Net Banking | Q13: =IF(H13="","",H13) -> 2544.83 | R13: =IF(I13="","",I13) -> 296.64
A14: ORD-0217 | B14: 2025-09-30 | C14: West | D14: Home | E14: Bedsheet | F14: Existing | G14: 5 | H14: 6770.92 | I14: 1477.31 | J14: Net Banking | K14: =PROPER(TRIM(C14)) -> West | L14: =PROPER(TRIM(D14)) -> Home | M14: =PROPER(TRIM(E14)) -> Bedsheet | N14: =IF(OR(H14="",I14="",J14="",F14=""),"Review","OK") -> OK | O14: =IF(TRIM(F14)="","Review",PROPER(TRIM(F14))) -> Existing | P14: =IF(TRIM(J14)="","Review",PROPER(TRIM(J14))) -> Net Banking | Q14: =IF(H14="","",H14) -> 6770.92 | R14: =IF(I14="","",I14) -> 1477.31
A15: ORD-0235 | B15: 2025-03-31 | C15: West | D15: Home | E15: Bedsheet | F15: Existing | G15: 3 | H15: 4256.94 | I15: 819.98 | J15: Cash | K15: =PROPER(TRIM(C15)) -> West | L15: =PROPER(TRIM(D15)) -> Home | M15: =PROPER(TRIM(E15)) -> Bedsheet | N15: =IF(OR(H15="",I15="",J15="",F15=""),"Review","OK") -> OK | O15: =IF(TRIM(F15)="","Review",PROPER(TRIM(F15))) -> Existing | P15: =IF(TRIM(J15)="","Review",PROPER(TRIM(J15))) -> Cash | Q15: =IF(H15="","",H15) -> 4256.94 | R15: =IF(I15="","",I15) -> 819.98
A16: ORD-0239 | B16: 2025-03-10 | C16: West | D16: Home | E16: Bedsheet | F16: New | G16: 3 | H16: 4296.29 | I16: -4.78 | J16: Net Banking | K16: =PROPER(TRIM(C16)) -> West | L16: =PROPER(TRIM(D16)) -> Home | M16: =PROPER(TRIM(E16)) -> Bedsheet | N16: =IF(OR(H16="",I16="",J16="",F16=""),"Review","OK") -> OK | O16: =IF(TRIM(F16)="","Review",PROPER(TRIM(F16))) -> New | P16: =IF(TRIM(J16)="","Review",PROPER(TRIM(J16))) -> Net Banking | Q16: =IF(H16="","",H16) -> 4296.29 | R16: =IF(I16="","",I16) -> -4.78
A17: ORD-0269 | B17: 2025-12-24 | C17: West | D17: Home | E17: Bedsheet | F17: New | G17: 5 | H17: 7668.47 | I17: -566.15 | J17: UPI | K17: =PROPER(TRIM(C17)) -> West | L17: =PROPER(TRIM(D17)) -> Home | M17: =PROPER(TRIM(E17)) -> Bedsheet | N17: =IF(OR(H17="",I17="",J17="",F17=""),"Review","OK") -> OK | O17: =IF(TRIM(F17)="","Review",PROPER(TRIM(F17))) -> New | P17: =IF(TRIM(J17)="","Review",PROPER(TRIM(J17))) -> Upi | Q17: =IF(H17="","",H17) -> 7668.47 | R17: =IF(I17="","",I17) -> -566.15
A18: ORD-0292 | B18: 2025-08-05 | C18: West | D18: Home | E18: Bedsheet | F18: New | G18: 2 | H18: 2661.5 | I18: -65.23 | J18: Net Banking | K18: =PROPER(TRIM(C18)) -> West | L18: =PROPER(TRIM(D18)) -> Home | M18: =PROPER(TRIM(E18)) -> Bedsheet | N18: =IF(OR(H18="",I18="",J18="",F18=""),"Review","OK") -> OK | O18: =IF(TRIM(F18)="","Review",PROPER(TRIM(F18))) -> New | P18: =IF(TRIM(J18)="","Review",PROPER(TRIM(J18))) -> Net Banking | Q18: =IF(H18="","",H18) -> 2661.5 | R18: =IF(I18="","",I18) -> -65.23
A19: ORD-0049 | B19: 2025-10-24 | C19: East | D19: Home | E19: Blender | F19: Existing | G19: 3 | H19: 9190.87 | I19: 687.11 | J19: Net Banking | K19: =PROPER(TRIM(C19)) -> East | L19: =PROPER(TRIM(D19)) -> Home | M19: =PROPER(TRIM(E19)) -> Blender | N19: =IF(OR(H19="",I19="",J19="",F19=""),"Review","OK") -> OK | O19: =IF(TRIM(F19)="","Review",PROPER(TRIM(F19))) -> Existing | P19: =IF(TRIM(J19)="","Review",PROPER(TRIM(J19))) -> Net Banking | Q19: =IF(H19="","",H19) -> 9190.87 | R19: =IF(I19="","",I19) -> 687.11
A20: ORD-0096 | B20: 2025-09-23 | C20: East | D20: Home | E20: Blender | F20: Existing | G20: 5 | H20: 15878.32 | I20: -960.42 | J20: Net Banking | K20: =PROPER(TRIM(C20)) -> East | L20: =PROPER(TRIM(D20)) -> Home | M20: =PROPER(TRIM(E20)) -> Blender | N20: =IF(OR(H20="",I20="",J20="",F20=""),"Review","OK") -> OK | O20: =IF(TRIM(F20)="","Review",PROPER(TRIM(F20))) -> Existing | P20: =IF(TRIM(J20)="","Review",PROPER(TRIM(J20))) -> Net Banking | Q20: =IF(H20="","",H20) -> 15878.32 | R20: =IF(I20="","",I20) -> -960.42
A21: ORD-0191 | B21: 2025-07-09 | C21: East | D21: Home | E21: Blender | F21: Existing | G21: 5 | H21: 14891 | I21: 1220.65 | J21: UPI | K21: =PROPER(TRIM(C21)) -> East | L21: =PROPER(TRIM(D21)) -> Home | M21: =PROPER(TRIM(E21)) -> Blender | N21: =IF(OR(H21="",I21="",J21="",F21=""),"Review","OK") -> OK | O21: =IF(TRIM(F21)="","Review",PROPER(TRIM(F21))) -> Existing | P21: =IF(TRIM(J21)="","Review",PROPER(TRIM(J21))) -> Upi | Q21: =IF(H21="","",H21) -> 14891 | R21: =IF(I21="","",I21) -> 1220.65
A22: ORD-0200 | B22: 2025-03-24 | C22: East | D22: Home | E22: Blender | F22: New | G22: 1 | H22: 3211.59 | I22: 94.69 | J22: Cash | K22: =PROPER(TRIM(C22)) -> East | L22: =PROPER(TRIM(D22)) -> Home | M22: =PROPER(TRIM(E22)) -> Blender | N22: =IF(OR(H22="",I22="",J22="",F22=""),"Review","OK") -> OK | O22: =IF(TRIM(F22)="","Review",PROPER(TRIM(F22))) -> New | P22: =IF(TRIM(J22)="","Review",PROPER(TRIM(J22))) -> Cash | Q22: =IF(H22="","",H22) -> 3211.59 | R22: =IF(I22="","",I22) -> 94.69
... A154: ORD-0287 | B154: 2025-11-14 | C154: West | D154: Electronics | E154: Headphones | F154: Existing | G154: 3 | H154: 6760.15 | I154: 422.17 | J154: Net Banking | K154: =PROPER(TRIM(C154)) -> West | L154: =PROPER(TRIM(D154)) -> Electronics | M154: =PROPER(TRIM(E154)) -> Headphones | N154: =IF(OR(H154="",I154="",J154="",F154=""),"Review","OK") -> OK | O154: =IF(TRIM(F154)="","Review",PROPER(TRIM(F154))) -> Existing | P154: =IF(TRIM(J154)="","Review",PROPER(TRIM(J154))) -> Net Banking | Q154: =IF(H154="","",H154) -> 6760.15 | R154: =IF(I154="","",I154) -> 422.17
A155: ORD-0091 | B155: 2025-06-15 | C155: East | D155: Clothing | E155: Jacket | G155: 5 | H155: 9987.69 | I155: 754.37 | J155: UPI | K155: =PROPER(TRIM(C155)) -> East | L155: =PROPER(TRIM(D155)) -> Clothing | M155: =PROPER(TRIM(E155)) -> Jacket | N155: =IF(OR(H155="",I155="",J155="",F155=""),"Review","OK") -> Review | O155: =IF(TRIM(F155)="","Review",PROPER(TRIM(F155))) -> Review | P155: =IF(TRIM(J155)="","Review",PROPER(TRIM(J155))) -> Upi | Q155: =IF(H155="","",H155) -> 9987.69 | R155: =IF(I155="","",I155) -> 754.37
A156: ORD-0281 | B156: 2025-07-04 | C156: East | D156: Clothing | E156: Jacket | F156: New | G156: 1 | H156: 1982.29 | I156: 61.4 | J156: Card | K156: =PROPER(TRIM(C156)) -> East | L156: =PROPER(TRIM(D156)) -> Clothing | M156: =PROPER(TRIM(E156)) -> Jacket | N156: =IF(OR(H156="",I156="",J156="",F156=""),"Review","OK") -> OK | O156: =IF(TRIM(F156)="","Review",PROPER(TRIM(F156))) -> New | P156: =IF(TRIM(J156)="","Review",PROPER(TRIM(J156))) -> Card | Q156: =IF(H156="","",H156) -> 1982.29 | R156: =IF(I156="","",I156) -> 61.4
A157: ORD-0036 | B157: 2025-01-23 | C157: North | D157: Clothing | E157: Jacket | F157: Existing | G157: 1 | H157: 2259.09 | I157: 493.76 | J157: Card | K157: =PROPER(TRIM(C157)) -> North | L157: =PROPER(TRIM(D157)) -> Clothing | M157: =PROPER(TRIM(E157)) -> Jacket | N157: =IF(OR(H157="",I157="",J157="",F157=""),"Review","OK") -> OK | O157: =IF(TRIM(F157)="","Review",PROPER(TRIM(F157))) -> Existing | P157: =IF(TRIM(J157)="","Review",PROPER(TRIM(J157))) -> Card | Q157: =IF(H157="","",H157) -> 2259.09 | R157: =IF(I157="","",I157) -> 493.76
A158: ORD-0155 | B158: 2025-05-21 | C158: North | D158: Clothing | E158: Jacket | F158: Existing | G158: 4 | H158: 8698.29 | I158: 252.38 | J158: UPI | K158: =PROPER(TRIM(C158)) -> North | L158: =PROPER(TRIM(D158)) -> Clothing | M158: =PROPER(TRIM(E158)) -> Jacket | N158: =IF(OR(H158="",I158="",J158="",F158=""),"Review","OK") -> OK | O158: =IF(TRIM(F158)="","Review",PROPER(TRIM(F158))) -> Existing | P158: =IF(TRIM(J158)="","Review",PROPER(TRIM(J158))) -> Upi | Q158: =IF(H158="","",H158) -> 8698.29 | R158: =IF(I158="","",I158) -> 252.38
A159: ORD-0197 | B159: 2025-10-10 | C159: South | D159: Clothing | E159: Jacket | F159: New | G159: 3 | H159: 6671.31 | I159: 352.3 | J159: UPI | K159: =PROPER(TRIM(C159)) -> South | L159: =PROPER(TRIM(D159)) -> Clothing | M159: =PROPER(TRIM(E159)) -> Jacket | N159: =IF(OR(H159="",I159="",J159="",F159=""),"Review","OK") -> OK | O159: =IF(TRIM(F159)="","Review",PROPER(TRIM(F159))) -> New | P159: =IF(TRIM(J159)="","Review",PROPER(TRIM(J159))) -> Upi | Q159: =IF(H159="","",H159) -> 6671.31 | R159: =IF(I159="","",I159) -> 352.3
A160: ORD-0210 | B160: 2025-05-04 | C160: South | D160: Clothing | E160: Jacket | F160: Existing | G160: 1 | H160: 2395.9 | I160: 244.29 | J160: UPI | K160: =PROPER(TRIM(C160)) -> South | L160: =PROPER(TRIM(D160)) -> Clothing | M160: =PROPER(TRIM(E160)) -> Jacket | N160: =IF(OR(H160="",I160="",J160="",F160=""),"Review","OK") -> OK | O160: =IF(TRIM(F160)="","Review",PROPER(TRIM(F160))) -> Existing | P160: =IF(TRIM(J160)="","Review",PROPER(TRIM(J160))) -> Upi | Q160: =IF(H160="","",H160) -> 2395.9 | R160: =IF(I160="","",I160) -> 244.29
A161: ORD-0284 | B161: 2025-10-20 | C161: South | D161: Clothing | E161: Jacket | F161: Existing | G161: 5 | H161: 11891.46 | I161: 3236.17 | J161: Card | K161: =PROPER(TRIM(C161)) -> South | L161: =PROPER(TRIM(D161)) -> Clothing | M161: =PROPER(TRIM(E161)) -> Jacket | N161: =IF(OR(H161="",I161="",J161="",F161=""),"Review","OK") -> OK | O161: =IF(TRIM(F161)="","Review",PROPER(TRIM(F161))) -> Existing | P161: =IF(TRIM(J161)="","Review",PROPER(TRIM(J161))) -> Card | Q161: =IF(H161="","",H161) -> 11891.46 | R161: =IF(I161="","",I161) -> 3236.17
A162: ORD-0131 | B162: 2025-02-02 | C162: West | D162: Clothing | E162: Jacket | F162: Existing | G162: 2 | H162: 4612.71 | I162: 504.59 | J162: Cash | K162: =PROPER(TRIM(C162)) -> West | L162: =PROPER(TRIM(D162)) -> Clothing | M162: =PROPER(TRIM(E162)) -> Jacket | N162: =IF(OR(H162="",I162="",J162="",F162=""),"Review","OK") -> OK | O162: =IF(TRIM(F162)="","Review",PROPER(TRIM(F162))) -> Existing | P162: =IF(TRIM(J162)="","Review",PROPER(TRIM(J162))) -> Cash | Q162: =IF(H162="","",H162) -> 4612.71 | R162: =IF(I162="","",I162) -> 504.59
A163: ORD-0148 | B163: 2025-03-08 | C163: West | D163: Clothing | E163: Jacket | F163: New | G163: 1 | H163: 2198.85 | I163: 164.99 | J163: Cash | K163: =PROPER(TRIM(C163)) -> West | L163: =PROPER(TRIM(D163)) -> Clothing | M163: =PROPER(TRIM(E163)) -> Jacket | N163: =IF(OR(H163="",I163="",J163="",F163=""),"Review","OK") -> OK | O163: =IF(TRIM(F163)="","Review",PROPER(TRIM(F163))) -> New | P163: =IF(TRIM(J163)="","Review",PROPER(TRIM(J163))) -> Cash | Q163: =IF(H163="","",H163) -> 2198.85 | R163: =IF(I163="","",I163) -> 164.99
A164: ORD-0172 | B164: 2025-05-01 | C164: West | D164: Clothing | E164: Jacket | F164: New | G164: 4 | H164: 8013.73 | I164: 807.16 | J164: Cash | K164: =PROPER(TRIM(C164)) -> West | L164: =PROPER(TRIM(D164)) -> Clothing | M164: =PROPER(TRIM(E164)) -> Jacket | N164: =IF(OR(H164="",I164="",J164="",F164=""),"Review","OK") -> OK | O164: =IF(TRIM(F164)="","Review",PROPER(TRIM(F164))) -> New | P164: =IF(TRIM(J164)="","Review",PROPER(TRIM(J164))) -> Cash | Q164: =IF(H164="","",H164) -> 8013.73 | R164: =IF(I164="","",I164) -> 807.16
A165: ORD-0275 | B165: 2025-12-31 | C165: West | D165: Clothing | E165: Jacket | F165: New | G165: 2 | H165: 4476.59 | I165: 854.19 | J165: Cash | K165: =PROPER(TRIM(C165)) -> West | L165: =PROPER(TRIM(D165)) -> Clothing | M165: =PROPER(TRIM(E165)) -> Jacket | N165: =IF(OR(H165="",I165="",J165="",F165=""),"Review","OK") -> OK | O165: =IF(TRIM(F165)="","Review",PROPER(TRIM(F165))) -> New | P165: =IF(TRIM(J165)="","Review",PROPER(TRIM(J165))) -> Cash | Q165: =IF(H165="","",H165) -> 4476.59 | R165: =IF(I165="","",I165) -> 854.19
A166: ORD-0119 | B166: 2025-02-08 | C166: South | D166: clothing | E166: Jeans | F166: New | G166: 3 | H166: 5092.06 | I166: 451.15 | J166: Net Banking | K166: =PROPER(TRIM(C166)) -> South | L166: =PROPER(TRIM(D166)) -> Clothing | M166: =PROPER(TRIM(E166)) -> Jeans | N166: =IF(OR(H166="",I166="",J166="",F166=""),"Review","OK") -> OK | O166: =IF(TRIM(F166)="","Review",PROPER(TRIM(F166))) -> New | P166: =IF(TRIM(J166)="","Review",PROPER(TRIM(J166))) -> Net Banking | Q166: =IF(H166="","",H166) -> 5092.06 | R166: =IF(I166="","",I166) -> 451.15
A167: ORD-0094 | B167: 2025-03-24 | C167: East | D167: Clothing | E167: Jeans | F167: Existing | G167: 4 | H167: 6186.63 | I167: 997.58 | J167: Net Banking | K167: =PROPER(TRIM(C167)) -> East | L167: =PROPER(TRIM(D167)) -> Clothing | M167: =PROPER(TRIM(E167)) -> Jeans | N167: =IF(OR(H167="",I167="",J167="",F167=""),"Review","OK") -> OK | O167: =IF(TRIM(F167)="","Review",PROPER(TRIM(F167))) -> Existing | P167: =IF(TRIM(J167)="","Review",PROPER(TRIM(J167))) -> Net Banking | Q167: =IF(H167="","",H167) -> 6186.63 | R167: =IF(I167="","",I167) -> 997.58
... A170: ORD-0226 | B170: 2025-02-10 | C170: East | D170: Clothing | E170: Jeans | F170: Existing | G170: 2 | H170: 3065.89 | I170: 72.19 | J170: Cash | K170: =PROPER(TRIM(C170)) -> East | L170: =PROPER(TRIM(D170)) -> Clothing | M170: =PROPER(TRIM(E170)) -> Jeans | N170: =IF(OR(H170="",I170="",J170="",F170=""),"Review","OK") -> OK | O170: =IF(TRIM(F170)="","Review",PROPER(TRIM(F170))) -> Existing | P170: =IF(TRIM(J170)="","Review",PROPER(TRIM(J170))) -> Cash | Q170: =IF(H170="","",H170) -> 3065.89 | R170: =IF(I170="","",I170) -> 72.19
A171: ORD-0064 | B171: 2025-01-10 | C171: North | D171: Clothing | E171: Jeans | F171: Existing | G171: 4 | H171: 6082.91 | I171: -307.27 | K171: =PROPER(TRIM(C171)) -> North | L171: =PROPER(TRIM(D171)) -> Clothing | M171: =PROPER(TRIM(E171)) -> Jeans | N171: =IF(OR(H171="",I171="",J171="",F171=""),"Review","OK") -> Review | O171: =IF(TRIM(F171)="","Review",PROPER(TRIM(F171))) -> Existing | P171: =IF(TRIM(J171)="","Review",PROPER(TRIM(J171))) -> Review | Q171: =IF(H171="","",H171) -> 6082.91 | R171: =IF(I171="","",I171) -> -307.27
A172: ORD-0085 | B172: 2025-11-14 | C172: North | D172: Clothing | E172: Jeans | F172: New | G172: 5 | H172: 8784.05 | I172: 262.97 | J172: Card | K172: =PROPER(TRIM(C172)) -> North | L172: =PROPER(TRIM(D172)) -> Clothing | M172: =PROPER(TRIM(E172)) -> Jeans | N172: =IF(OR(H172="",I172="",J172="",F172=""),"Review","OK") -> OK | O172: =IF(TRIM(F172)="","Review",PROPER(TRIM(F172))) -> New | P172: =IF(TRIM(J172)="","Review",PROPER(TRIM(J172))) -> Card | Q172: =IF(H172="","",H172) -> 8784.05 | R172: =IF(I172="","",I172) -> 262.97
A173: ORD-0127 | B173: 2025-08-21 | C173: North | D173: Clothing | E173: Jeans | F173: New | G173: 2 | H173: 3499.65 | I173: 915.66 | J173: UPI | K173: =PROPER(TRIM(C173)) -> North | L173: =PROPER(TRIM(D173)) -> Clothing | M173: =PROPER(TRIM(E173)) -> Jeans | N173: =IF(OR(H173="",I173="",J173="",F173=""),"Review","OK") -> OK | O173: =IF(TRIM(F173)="","Review",PROPER(TRIM(F173))) -> New | P173: =IF(TRIM(J173)="","Review",PROPER(TRIM(J173))) -> Upi | Q173: =IF(H173="","",H173) -> 3499.65 | R173: =IF(I173="","",I173) -> 915.66
...

Sheet Analysis_Data
A1: Order ID | B1: Order Date | C1: Region | D1: Category | E1: Product | F1: Customer Type | G1: Quantity | H1: Sales | I1: Profit | J1: Payment Mode | K1: Data Quality Status
A2: =Raw_Data!A2 -> ORD-0001 | B2: 2025-03-13 | C2: =PROPER(TRIM(Raw_Data!C2)) -> North | D2: =PROPER(TRIM(Raw_Data!D2)) -> Home | E2: =PROPER(TRIM(Raw_Data!E2)) -> Blender | F2: =IF(TRIM(Raw_Data!F2)="","Review",PROPER(TRIM(Raw_Data!F2))) -> New | G2: =Raw_Data!G2 -> 1 | H2: =IF(Raw_Data!H2="","",Raw_Data!H2) -> 3354.59 | I2: =IF(Raw_Data!I2="","",Raw_Data!I2) -> 27.38 | J2: =IF(TRIM(Raw_Data!J2)="","Review",PROPER(TRIM(Raw_Data!J2))) -> Net Banking | K2: =IF(OR(H2="",I2="",J2="Review",F2="Review"),"Review","OK") -> OK
A3: =Raw_Data!A3 -> ORD-0002 | B3: 2025-01-14 | C3: =PROPER(TRIM(Raw_Data!C3)) -> South | D3: =PROPER(TRIM(Raw_Data!D3)) -> Electronics | E3: =PROPER(TRIM(Raw_Data!E3)) -> Laptop | F3: =IF(TRIM(Raw_Data!F3)="","Review",PROPER(TRIM(Raw_Data!F3))) -> Existing | G3: =Raw_Data!G3 -> 1 | H3: =IF(Raw_Data!H3="","",Raw_Data!H3) -> 49073.83 | I3: =IF(Raw_Data!I3="","",Raw_Data!I3) -> 5001.99 | J3: =IF(TRIM(Raw_Data!J3)="","Review",PROPER(TRIM(Raw_Data!J3))) -> Card | K3: =IF(OR(H3="",I3="",J3="Review",F3="Review"),"Review","OK") -> OK
A4: =Raw_Data!A4 -> ORD-0003 | B4: 2025-03-23 | C4: =PROPER(TRIM(Raw_Data!C4)) -> West | D4: =PROPER(TRIM(Raw_Data!D4)) -> Clothing | E4: =PROPER(TRIM(Raw_Data!E4)) -> Dress | F4: =IF(TRIM(Raw_Data!F4)="","Review",PROPER(TRIM(Raw_Data!F4))) -> Existing | G4: =Raw_Data!G4 -> 3 | H4: =IF(Raw_Data!H4="","",Raw_Data!H4) -> 6052.75 | I4: =IF(Raw_Data!I4="","",Raw_Data!I4) -> -470.06 | J4: =IF(TRIM(Raw_Data!J4)="","Review",PROPER(TRIM(Raw_Data!J4))) -> Cash | K4: =IF(OR(H4="",I4="",J4="Review",F4="Review"),"Review","OK") -> OK
A5: =Raw_Data!A5 -> ORD-0004 | B5: 2025-07-03 | C5: =PROPER(TRIM(Raw_Data!C5)) -> East | D5: =PROPER(TRIM(Raw_Data!D5)) -> Electronics | E5: =PROPER(TRIM(Raw_Data!E5)) -> Headphones | F5: =IF(TRIM(Raw_Data!F5)="","Review",PROPER(TRIM(Raw_Data!F5))) -> Existing | G5: =Raw_Data!G5 -> 3 | H5: =IF(Raw_Data!H5="","",Raw_Data!H5) -> 6903.32 | I5: =IF(Raw_Data!I5="","",Raw_Data!I5) -> 391.93 | J5: =IF(TRIM(Raw_Data!J5)="","Review",PROPER(TRIM(Raw_Data!J5))) -> Upi | K5: =IF(OR(H5="",I5="",J5="Review",F5="Review"),"Review","OK") -> OK
A6: =Raw_Data!A6 -> ORD-0005 | B6: 2025-02-10 | C6: =PROPER(TRIM(Raw_Data!C6)) -> East | D6: =PROPER(TRIM(Raw_Data!D6)) -> Home | E6: =PROPER(TRIM(Raw_Data!E6)) -> Cookware Set | F6: =IF(TRIM(Raw_Data!F6)="","Review",PROPER(TRIM(Raw_Data!F6))) -> Existing | G6: =Raw_Data!G6 -> 5 | H6: =IF(Raw_Data!H6="","",Raw_Data!H6) -> 12949.51 | I6: =IF(Raw_Data!I6="","",Raw_Data!I6) -> 3263.62 | J6: =IF(TRIM(Raw_Data!J6)="","Review",PROPER(TRIM(Raw_Data!J6))) -> Card | K6: =IF(OR(H6="",I6="",J6="Review",F6="Review"),"Review","OK") -> OK
A7: =Raw_Data!A7 -> ORD-0006 | B7: 2025-02-10 | C7: =PROPER(TRIM(Raw_Data!C7)) -> South | D7: =PROPER(TRIM(Raw_Data!D7)) -> Home | E7: =PROPER(TRIM(Raw_Data!E7)) -> Blender | F7: =IF(TRIM(Raw_Data!F7)="","Review",PROPER(TRIM(Raw_Data!F7))) -> New | G7: =Raw_Data!G7 -> 1 | H7: =IF(Raw_Data!H7="","",Raw_Data!H7) -> 3303.21 | I7: =IF(Raw_Data!I7="","",Raw_Data!I7) -> 655.04 | J7: =IF(TRIM(Raw_Data!J7)="","Review",PROPER(TRIM(Raw_Data!J7))) -> Net Banking | K7: =IF(OR(H7="",I7="",J7="Review",F7="Review"),"Review","OK") -> OK
A8: =Raw_Data!A8 -> ORD-0007 | B8: 2025-12-10 | C8: =PROPER(TRIM(Raw_Data!C8)) -> East | D8: =PROPER(TRIM(Raw_Data!D8)) -> Clothing | E8: =PROPER(TRIM(Raw_Data!E8)) -> Sneakers | F8: =IF(TRIM(Raw_Data!F8)="","Review",PROPER(TRIM(Raw_Data!F8))) -> New | G8: =Raw_Data!G8 -> 3 | H8: =IF(Raw_Data!H8="","",Raw_Data!H8) -> 9791.57 | I8: =IF(Raw_Data!I8="","",Raw_Data!I8) -> 468.99 | J8: =IF(TRIM(Raw_Data!J8)="","Review",PROPER(TRIM(Raw_Data!J8))) -> Card | K8: =IF(OR(H8="",I8="",J8="Review",F8="Review"),"Review","OK") -> OK
A9: =Raw_Data!A9 -> ORD-0008 | B9: 2025-11-24 | C9: =PROPER(TRIM(Raw_Data!C9)) -> South | D9: =PROPER(TRIM(Raw_Data!D9)) -> Home | E9: =PROPER(TRIM(Raw_Data!E9)) -> Desk Lamp | F9: =IF(TRIM(Raw_Data!F9)="","Review",PROPER(TRIM(Raw_Data!F9))) -> Existing | G9: =Raw_Data!G9 -> 2 | H9: =IF(Raw_Data!H9="","",Raw_Data!H9) -> 1786.41 | I9: =IF(Raw_Data!I9="","",Raw_Data!I9) -> 30.69 | J9: =IF(TRIM(Raw_Data!J9)="","Review",PROPER(TRIM(Raw_Data!J9))) -> Upi | K9: =IF(OR(H9="",I9="",J9="Review",F9="Review"),"Review","OK") -> OK
A10: =Raw_Data!A10 -> ORD-0009 | B10: 2025-10-18 | C10: =PROPER(TRIM(Raw_Data!C10)) -> East | D10: =PROPER(TRIM(Raw_Data!D10)) -> Electronics | E10: =PROPER(TRIM(Raw_Data!E10)) -> Laptop | F10: =IF(TRIM(Raw_Data!F10)="","Review",PROPER(TRIM(Raw_Data!F10))) -> New | G10: =Raw_Data!G10 -> 3 | H10: =IF(Raw_Data!H10="","",Raw_Data!H10) -> 152916.34 | I10: =IF(Raw_Data!I10="","",Raw_Data!I10) -> -8589.63 | J10: =IF(TRIM(Raw_Data!J10)="","Review",PROPER(TRIM(Raw_Data!J10))) -> Net Banking | K10: =IF(OR(H10="",I10="",J10="Review",F10="Review"),"Review","OK") -> OK
A11: =Raw_Data!A11 -> ORD-0010 | B11: 2025-10-15 | C11: =PROPER(TRIM(Raw_Data!C11)) -> East | D11: =PROPER(TRIM(Raw_Data!D11)) -> Clothing | E11: =PROPER(TRIM(Raw_Data!E11)) -> Sneakers | F11: =IF(TRIM(Raw_Data!F11)="","Review",PROPER(TRIM(Raw_Data!F11))) -> Existing | G11: =Raw_Data!G11 -> 2 | H11: =IF(Raw_Data!H11="","",Raw_Data!H11) -> 6670.83 | I11: =IF(Raw_Data!I11="","",Raw_Data!I11) -> 58.61 | J11: =IF(TRIM(Raw_Data!J11)="","Review",PROPER(TRIM(Raw_Data!J11))) -> Net Banking | K11: =IF(OR(H11="",I11="",J11="Review",F11="Review"),"Review","OK") -> OK
A12: =Raw_Data!A12 -> ORD-0011 | B12: 2025-01-25 | C12: =PROPER(TRIM(Raw_Data!C12)) -> North | D12: =PROPER(TRIM(Raw_Data!D12)) -> Clothing | E12: =PROPER(TRIM(Raw_Data!E12)) -> T-Shirt | F12: =IF(TRIM(Raw_Data!F12)="","Review",PROPER(TRIM(Raw_Data!F12))) -> New | G12: =Raw_Data!G12 -> 2 | H12: =IF(Raw_Data!H12="","",Raw_Data!H12) -> 1402.67 | I12: =IF(Raw_Data!I12="","",Raw_Data!I12) -> -66.31 | J12: =IF(TRIM(Raw_Data!J12)="","Review",PROPER(TRIM(Raw_Data!J12))) -> Card | K12: =IF(OR(H12="",I12="",J12="Review",F12="Review"),"Review","OK") -> OK
A13: =Raw_Data!A13 -> ORD-0012 | B13: 2025-08-28 | C13: =PROPER(TRIM(Raw_Data!C13)) -> East | D13: =PROPER(TRIM(Raw_Data!D13)) -> Home | E13: =PROPER(TRIM(Raw_Data!E13)) -> Cookware Set | F13: =IF(TRIM(Raw_Data!F13)="","Review",PROPER(TRIM(Raw_Data!F13))) -> New | G13: =Raw_Data!G13 -> 5 | H13: =IF(Raw_Data!H13="","",Raw_Data!H13) -> 12777.88 | I13: =IF(Raw_Data!I13="","",Raw_Data!I13) -> 733.23 | J13: =IF(TRIM(Raw_Data!J13)="","Review",PROPER(TRIM(Raw_Data!J13))) -> Upi | K13: =IF(OR(H13="",I13="",J13="Review",F13="Review"),"Review","OK") -> OK
... A301: =Raw_Data!A301 -> ORD-0300 | B301: 2025-09-22 | C301: =PROPER(TRIM(Raw_Data!C301)) -> South | D301: =PROPER(TRIM(Raw_Data!D301)) -> Home | E301: =PROPER(TRIM(Raw_Data!E301)) -> Blender | F301: =IF(TRIM(Raw_Data!F301)="","Review",PROPER(TRIM(Raw_Data!F301))) -> New | G301: =Raw_Data!G301 -> 2 | H301: =IF(Raw_Data!H301="","",Raw_Data!H301) -> 6950.3 | I301: =IF(Raw_Data!I301="","",Raw_Data!I301) -> 1296.76 | J301: =IF(TRIM(Raw_Data!J301)="","Review",PROPER(TRIM(Raw_Data!J301))) -> Cash | K301: =IF(OR(H301="",I301="",J301="Review",F301="Review"),"Review","OK") -> OK

Sheet Pivot_Analysis
A1: Data Quality Check | B1: Result
A2: Total Orders | B2: 300
A3: Missing Sales | B3: 1
A4: Missing Profit | B4: 1
A5: Missing Payment Mode | B5: 1
A6: Missing Customer Type | B6: 1
A7: Duplicate Order IDs | B7: 0
A8: Rows Requiring Review | B8: 4
A10: Row Labels | B10: Sum of Sales | D10: Row Labels | E10: Sum of Profit | G10: Row Labels | H10: Sum of Sales | J10: Row Labels | K10: Sum of Profit
A11: East | B11: 2077592 | D11: East | E11: 268356.6 | G11: Clothing | H11: 577541.95 | J11: Clothing | K11: 60838.58
A12: North | B12: 1846118.5 | D12: North | E12: 126539.77 | G12: Electronics | H12: 5202334.7 | J12: Electronics | K12: 463709.84
A13: South | B13: 1424828.3 | D13: South | E13: 140885.18 | G13: Home | H13: 970582.12 | J13: Home | K13: 97134.49
A14: West | B14: 1401920.1 | D14: West | E14: 85901.36 | G14: Grand Total | H14: 6750458.8 | J14: Grand Total | K14: 621682.91
A15: Grand Total | B15: 6750458.8 | D15: Grand Total | E15: 621682.91
A20: Row Labels | B20: Sum of Sales | D20: Row Labels | E20: Sum of Sales | J20: Count of Order ID | K20: Sum of Sales | L20: Sum of Profit
A21: Existing | B21: 3430442 | D21: Card | E21: 1590544.1 | J21: 300 | K21: 6750458.8 | L21: 621682.91
A22: New | B22: 3310029.1 | D22: Cash | E22: 1673942
A23: Review | B23: 9987.69 | D23: Net Banking | E23: 1825473.9
A24: Grand Total | B24: 6750458.8 | D24: Review | E24: 6082.91
D25: Upi | E25: 1654416
D26: Grand Total | E26: 6750458.8

Sheet Dashboard
A1: RETAIL SALES ANALYSIS DASHBOARD
A4: TOTAL SALES | D4: Total Profit | G4: Total Orders | J4: Avg. Order Value
A5: =Pivot_Analysis!K21 -> 6750458.8 | D5: =Pivot_Analysis!L21 -> 621682.91 | G5: =Pivot_Analysis!J21 -> 300 | J5: =IFERROR(A5/G5,0) -> 22501.529
